Traceback (most recent call last):
  File "/opt/hostedtoolcache/Python/3.9.17/x64/lib/python3.9/site-packages/jupyter_cache/executors/utils.py", line 58, in single_nb_execution
    executenb(
  File "/opt/hostedtoolcache/Python/3.9.17/x64/lib/python3.9/site-packages/nbclient/client.py", line 1305, in execute
    return NotebookClient(nb=nb, resources=resources, km=km, **kwargs).execute()
  File "/opt/hostedtoolcache/Python/3.9.17/x64/lib/python3.9/site-packages/jupyter_core/utils/__init__.py", line 166, in wrapped
    return loop.run_until_complete(inner)
  File "/opt/hostedtoolcache/Python/3.9.17/x64/lib/python3.9/asyncio/base_events.py", line 647, in run_until_complete
    return future.result()
  File "/opt/hostedtoolcache/Python/3.9.17/x64/lib/python3.9/site-packages/nbclient/client.py", line 705, in async_execute
    await self.async_execute_cell(
  File "/opt/hostedtoolcache/Python/3.9.17/x64/lib/python3.9/site-packages/nbclient/client.py", line 1058, in async_execute_cell
    await self._check_raise_for_error(cell, cell_index, exec_reply)
  File "/opt/hostedtoolcache/Python/3.9.17/x64/lib/python3.9/site-packages/nbclient/client.py", line 914, in _check_raise_for_error
    raise CellExecutionError.from_cell_and_msg(cell, exec_reply_content)
nbclient.exceptions.CellExecutionError: An error occurred while executing the following cell:
------------------
import plotly.express as px
from policyengine_core.charts import format_fig, BLUE_COLOR_SCALE, GRAY

fig = (
    px.bar(
        df[~df.error][::-1].sort_values(["year", "value"]),
        animation_frame="year",
        y="variable",
        x="value",
        color="model",
        barmode="group",
        orientation="h",
        custom_data=["text"],
        color_discrete_map={
            "Official": GRAY,
            # "Official (error)": GRAY,
            "PolicyEngine": BLUE_COLOR_SCALE[3],
            # "PolicyEngine (error)": BLUE_COLOR_SCALE[3],
            "UKMOD": BLUE_COLOR_SCALE[0],
            # "UKMOD (error)": BLUE_COLOR_SCALE[0],
        },
    )
    .update_layout(
        title="Errors against official estimates",
        xaxis_title="Budgetary impact (Â£bn)",
        yaxis_title="",
        legend_title="",
        xaxis_range=[-10, 300],
    )
    .update_traces(hovertemplate="%{customdata[0]}")
)
fig = format_fig(fig)
fig
------------------


[0;31m---------------------------------------------------------------------------[0m
[0;31mImportError[0m                               Traceback (most recent call last)
Cell [0;32mIn[2], line 2[0m
[1;32m      1[0m [38;5;28;01mimport[39;00m [38;5;21;01mplotly[39;00m[38;5;21;01m.[39;00m[38;5;21;01mexpress[39;00m [38;5;28;01mas[39;00m [38;5;21;01mpx[39;00m
[0;32m----> 2[0m [38;5;28;01mfrom[39;00m [38;5;21;01mpolicyengine_core[39;00m[38;5;21;01m.[39;00m[38;5;21;01mcharts[39;00m [38;5;28;01mimport[39;00m format_fig, BLUE_COLOR_SCALE, GRAY
[1;32m      4[0m fig [38;5;241m=[39m (
[1;32m      5[0m     px[38;5;241m.[39mbar(
[1;32m      6[0m         df[[38;5;241m~[39mdf[38;5;241m.[39merror][::[38;5;241m-[39m[38;5;241m1[39m][38;5;241m.[39msort_values([[38;5;124m"[39m[38;5;124myear[39m[38;5;124m"[39m, [38;5;124m"[39m[38;5;124mvalue[39m[38;5;124m"[39m]),
[0;32m   (...)[0m
[1;32m     30[0m     [38;5;241m.[39mupdate_traces(hovertemplate[38;5;241m=[39m[38;5;124m"[39m[38;5;124m%[39m[38;5;132;01m{customdata[0]}[39;00m[38;5;124m"[39m)
[1;32m     31[0m )
[1;32m     32[0m fig [38;5;241m=[39m format_fig(fig)

[0;31mImportError[0m: cannot import name 'BLUE_COLOR_SCALE' from 'policyengine_core.charts' (/opt/hostedtoolcache/Python/3.9.17/x64/lib/python3.9/site-packages/policyengine_core/charts/__init__.py)

